<?xml version="1.0"?>
<robot xmlns:xacro="http://ros.org/wiki/xacro"
       name="ur10_alone" >
  
  <xacro:macro name="elmo_linear_guide">
    
    <link name="elmo_linear_guide_stator">
      <visual>
        <origin xyz="1 0.0 -0.1" rpy="0 0 0" />
        <geometry>
          <box size="2.2 0.3 0.2"/>
        </geometry>
        <material name="DarkGrey">
          <color rgba="0.4 0.4 0.4 1.0"/>
        </material>
      </visual>
      <inertial>
          <origin xyz="0 0 0" rpy="0 0 0" />
          <mass value="1" />
          <inertia
            ixx="1.0" ixy="0.0" ixz="0.0"
            iyy="1.0" iyz="0.0"
            izz="1.0" />
      </inertial>
    </link>



    <link name="elmo_linear_guide_cursor">
      <visual>
        <origin xyz="0 0.0 -0.035" rpy="0 0 0" />
        <geometry>
          <box size="0.27 0.25 0.07"/>
        </geometry>
        <material name="">
          <color rgba="0.79216 0.81961 0.93333 1" />
        </material>
      </visual>
      <collision>
        <origin xyz="0 0.0 -0.035" rpy="0 0 0" />
        <geometry>
          <box size="0.27 0.25 0.07"/>
        </geometry>
        <material name="">
          <color rgba="0.79216 0.81961 0.93333 1" />
        </material>
      </collision>
      <inertial>
          <origin xyz="0 0 0" rpy="0 0 0" />
          <mass value="1" />
          <inertia
            ixx="1.0" ixy="0.0" ixz="0.0"
            iyy="1.0" iyz="0.0"
            izz="1.0" />
      </inertial>
    </link>
    
    <joint name="linear_motor_cursor_joint" type="prismatic">
      <parent link="elmo_linear_guide_stator" />
      <child link = "elmo_linear_guide_cursor" />
      <origin xyz="${0.27*0.5} 0.0 0.07" rpy="0.0 0.0 0" />
      <axis xyz="1 0 0" />
      <limit effort="495.0" lower="-0.005" upper="1.45" velocity="1"/>
    </joint>


    <transmission name="linear_motor_cursor_trans">
      <type>transmission_interface/SimpleTransmission</type>
      <joint name="linear_motor_cursor_joint">
        <hardwareInterface>hardware_interface/EffortJointInterface</hardwareInterface>
      </joint>
      <actuator name="linear_motor_cursor_motor">
        <mechanicalReduction>1</mechanicalReduction>
      </actuator>
    </transmission>

    
  </xacro:macro>
</robot>
